2025-02-26 14:55:03.624 | INFO     | System resources -> | CPUs: 120 on 0.00MHz | GPUs: 1 (NVIDIA A40) | RAM 442.63GB | (utils.logger:log_resources:11)
2025-02-26 14:55:03.624 | INFO     | Run using the following arguments: {'models': ['detect-gpt', 'ghostbuster'], 'dataset': 'brat-project/dipper/llama-3.3-70b-instruct/131538', 'device': 'cuda:0', 'n_samples': 402, 'chunk_size': 50, 'base_model_name': 'gpt2-xl', 'mask_filling_model_name': 't5-3b', 'cache_dir': '../resources', 'max_num_attempts': 20, 'disable_log_file': False, 'openai_key': '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', 'seed': 42, 'max_words': None, 'cut_sentences': False, 'use_detector_cache': True, 'checkpoint': None, 'buffer_size': 1, 'mask_top_p': 1.0, 'pct_words_masked': 0.3, 'n_perturbation': 100, 'span_length': 2, 'start_at': datetime.datetime(2025, 2, 26, 14, 55, 3, 222732), 'job_id': '137458'} (__main__:<module>:67)
2025-02-26 14:55:03.624 | INFO     | Running on seed 42 (utils.seeds:set_seeds:8)
2025-02-26 14:55:03.645 | SUCCESS  | Loaded data: "brat-project/dipper/llama-3.3-70b-instruct/131538" | Used indices: [0, 1, 2, 3, 4, 5, 6, 7, 8, 9, 10, 11, 12, 13, 14, 15, 16, 17, 18, 19, 20, 21, 22, 23, 24, 25, 26, 27, 28, 29, 30, 31, 32, 33, 34, 35, 36, 37, 38, 39, 40, 41, 42, 43, 44, 45, 46, 47, 48, 49, 50, 51, 52, 53, 54, 55, 56, 57, 58, 59, 60, 61, 62, 63, 64, 65, 66, 67, 68, 69, 70, 71, 72, 73, 74, 75, 76, 77, 78, 79, 80, 81, 82, 83, 84, 85, 86, 87, 88, 89, 90, 91, 92, 93, 94, 95, 96, 97, 98, 99, 100, 101, 102, 103, 104, 105, 106, 107, 108, 109, 110, 111, 112, 113, 114, 115, 116, 117, 118, 119, 120, 121, 122, 123, 124, 125, 126, 127, 128, 129, 130, 131, 132, 133, 134, 135, 136, 137, 138, 139, 140, 141, 142, 143, 144, 145, 146, 147, 148, 149, 150, 151, 152, 153, 154, 155, 156, 157, 158, 159, 160, 161, 162, 163, 164, 165, 166, 167, 168, 169, 170, 171, 172, 173, 174, 175, 176, 177, 178, 179, 180, 181, 182, 183, 184, 185, 186, 187, 188, 189, 190, 191, 192, 193, 194, 195, 196, 197, 198, 199, 200, 201, 202, 203, 204, 205, 206, 207, 208, 209, 210, 211, 212, 213, 214, 215, 216, 217, 218, 219, 220, 221, 222, 223, 224, 225, 226, 227, 228, 229, 230, 231, 232, 233, 234, 235, 236, 237, 238, 239, 240, 241, 242, 243, 244, 245, 246, 247, 248, 249, 250, 251, 252, 253, 254, 255, 256, 257, 258, 259, 260, 261, 262, 263, 264, 265, 266, 267, 268, 269, 270, 271, 272, 273, 274, 275, 276, 277, 278, 279, 280, 281, 282, 283, 284, 285, 286, 287, 288, 289, 290, 291, 292, 293, 294, 295, 296, 297, 298, 299, 300, 301, 302, 303, 304, 305, 306, 307, 308, 309, 310, 311, 312, 313, 314, 315, 316, 317, 318, 319, 320, 321, 322, 323, 324, 325, 326, 327, 328, 329, 330, 331, 332, 333, 334, 335, 336, 337, 338, 339, 340, 341, 342, 343, 344, 345, 346, 347, 348, 349, 350, 351, 352, 353, 354, 355, 356, 357, 358, 359, 360, 361, 362, 363, 364, 365, 366, 367, 368, 369, 370, 371, 372, 373, 374, 375, 376, 377, 378, 379, 380, 381, 382, 383, 384, 385, 386, 387, 388, 389, 390, 391, 392, 393, 394, 395, 396, 397, 398, 399, 400, 401] (utils.load_data:load_data:54)
2025-02-26 14:55:03.645 | INFO     | Executing Ghostbuster model (__main__:run:38)
2025-02-26 14:55:03.649 | INFO     | Human data hash: bde5f22229a96fe7d17e58593e1d57ef9689fa03f2132f3cef18b61267cce20b | LLM data hash: 6bb13ccb48847b11e6952172818e2fe457eb55a1f075422de99c1dc182e983dc (utils.args:add_data_hash_to_args:16)
2025-02-26 14:55:18.702 | ERROR    | An error has been caught in function '<module>', process 'MainProcess' (2408488), thread 'MainThread' (134400623101760): (__main__:<module>:69)
Traceback (most recent call last):

  File "/homes/lgehring/miniconda3/envs/BenchEduLLMDetect/lib/python3.10/site-packages/urllib3/connection.py", line 198, in _new_conn
    sock = connection.create_connection(
           │          └ <function create_connection at 0x7a3baa064280>
           └ <module 'urllib3.util.connection' from '/homes/lgehring/miniconda3/envs/BenchEduLLMDetect/lib/python3.10/site-packages/urllib...
  File "/homes/lgehring/miniconda3/envs/BenchEduLLMDetect/lib/python3.10/site-packages/urllib3/util/connection.py", line 60, in create_connection
    for res in socket.getaddrinfo(host, port, family, socket.SOCK_STREAM):
               │      │           │     │     │       │      └ <SocketKind.SOCK_STREAM: 1>
               │      │           │     │     │       └ <module 'socket' from '/homes/lgehring/miniconda3/envs/BenchEduLLMDetect/lib/python3.10/socket.py'>
               │      │           │     │     └ <AddressFamily.AF_UNSPEC: 0>
               │      │           │     └ 443
               │      │           └ 'openaipublic.blob.core.windows.net'
               │      └ <function getaddrinfo at 0x7a3c949dc700>
               └ <module 'socket' from '/homes/lgehring/miniconda3/envs/BenchEduLLMDetect/lib/python3.10/socket.py'>
  File "/homes/lgehring/miniconda3/envs/BenchEduLLMDetect/lib/python3.10/socket.py", line 955, in getaddrinfo
    for res in _socket.getaddrinfo(host, port, family, type, proto, flags):
               │       │           │     │     │       │     │      └ 0
               │       │           │     │     │       │     └ 0
               │       │           │     │     │       └ <SocketKind.SOCK_STREAM: 1>
               │       │           │     │     └ <AddressFamily.AF_UNSPEC: 0>
               │       │           │     └ 443
               │       │           └ 'openaipublic.blob.core.windows.net'
               │       └ <built-in function getaddrinfo>
               └ <module '_socket' from '/homes/lgehring/miniconda3/envs/BenchEduLLMDetect/lib/python3.10/lib-dynload/_socket.cpython-310-x86_...

socket.gaierror: [Errno -3] Temporary failure in name resolution


The above exception was the direct cause of the following exception:


Traceback (most recent call last):

  File "/homes/lgehring/miniconda3/envs/BenchEduLLMDetect/lib/python3.10/site-packages/urllib3/connectionpool.py", line 787, in urlopen
    response = self._make_request(
               │    └ <function HTTPConnectionPool._make_request at 0x7a3ba9e4fc70>
               └ <urllib3.connectionpool.HTTPSConnectionPool object at 0x7a3b99e747f0>
  File "/homes/lgehring/miniconda3/envs/BenchEduLLMDetect/lib/python3.10/site-packages/urllib3/connectionpool.py", line 488, in _make_request
    raise new_e
          └ NameResolutionError("<urllib3.connection.HTTPSConnection object at 0x7a3b99e74f40>: Failed to resolve 'openaipublic.blob.core...
  File "/homes/lgehring/miniconda3/envs/BenchEduLLMDetect/lib/python3.10/site-packages/urllib3/connectionpool.py", line 464, in _make_request
    self._validate_conn(conn)
    │    │              └ <urllib3.connection.HTTPSConnection object at 0x7a3b99e74f40>
    │    └ <function HTTPSConnectionPool._validate_conn at 0x7a3ba9e500d0>
    └ <urllib3.connectionpool.HTTPSConnectionPool object at 0x7a3b99e747f0>
  File "/homes/lgehring/miniconda3/envs/BenchEduLLMDetect/lib/python3.10/site-packages/urllib3/connectionpool.py", line 1093, in _validate_conn
    conn.connect()
    │    └ <function HTTPSConnection.connect at 0x7a3ba9e4c4c0>
    └ <urllib3.connection.HTTPSConnection object at 0x7a3b99e74f40>
  File "/homes/lgehring/miniconda3/envs/BenchEduLLMDetect/lib/python3.10/site-packages/urllib3/connection.py", line 704, in connect
    self.sock = sock = self._new_conn()
    │    │             │    └ <function HTTPConnection._new_conn at 0x7a3ba9e3bac0>
    │    │             └ <urllib3.connection.HTTPSConnection object at 0x7a3b99e74f40>
    │    └ None
    └ <urllib3.connection.HTTPSConnection object at 0x7a3b99e74f40>
  File "/homes/lgehring/miniconda3/envs/BenchEduLLMDetect/lib/python3.10/site-packages/urllib3/connection.py", line 205, in _new_conn
    raise NameResolutionError(self.host, self, e) from e
          │                   │    │     └ <urllib3.connection.HTTPSConnection object at 0x7a3b99e74f40>
          │                   │    └ <property object at 0x7a3baa0e4810>
          │                   └ <urllib3.connection.HTTPSConnection object at 0x7a3b99e74f40>
          └ <class 'urllib3.exceptions.NameResolutionError'>

urllib3.exceptions.NameResolutionError: <urllib3.connection.HTTPSConnection object at 0x7a3b99e74f40>: Failed to resolve 'openaipublic.blob.core.windows.net' ([Errno -3] Temporary failure in name resolution)


The above exception was the direct cause of the following exception:


Traceback (most recent call last):

  File "/homes/lgehring/miniconda3/envs/BenchEduLLMDetect/lib/python3.10/site-packages/requests/adapters.py", line 667, in send
    resp = conn.urlopen(
           │    └ <function HTTPConnectionPool.urlopen at 0x7a3ba9e4fe20>
           └ <urllib3.connectionpool.HTTPSConnectionPool object at 0x7a3b99e747f0>
  File "/homes/lgehring/miniconda3/envs/BenchEduLLMDetect/lib/python3.10/site-packages/urllib3/connectionpool.py", line 841, in urlopen
    retries = retries.increment(
              │       └ <function Retry.increment at 0x7a3baa066680>
              └ Retry(total=0, connect=None, read=False, redirect=None, status=None)
  File "/homes/lgehring/miniconda3/envs/BenchEduLLMDetect/lib/python3.10/site-packages/urllib3/util/retry.py", line 519, in increment
    raise MaxRetryError(_pool, url, reason) from reason  # type: ignore[arg-type]
          │             │      │    │            └ NameResolutionError("<urllib3.connection.HTTPSConnection object at 0x7a3b99e74f40>: Failed to resolve 'openaipublic.blob.core...
          │             │      │    └ NameResolutionError("<urllib3.connection.HTTPSConnection object at 0x7a3b99e74f40>: Failed to resolve 'openaipublic.blob.core...
          │             │      └ '/encodings/cl100k_base.tiktoken'
          │             └ <urllib3.connectionpool.HTTPSConnectionPool object at 0x7a3b99e747f0>
          └ <class 'urllib3.exceptions.MaxRetryError'>

urllib3.exceptions.MaxRetryError: HTTPSConnectionPool(host='openaipublic.blob.core.windows.net', port=443): Max retries exceeded with url: /encodings/cl100k_base.tiktoken (Caused by NameResolutionError("<urllib3.connection.HTTPSConnection object at 0x7a3b99e74f40>: Failed to resolve 'openaipublic.blob.core.windows.net' ([Errno -3] Temporary failure in name resolution)"))


During handling of the above exception, another exception occurred:


Traceback (most recent call last):

> File "/homes/lgehring/projects/BenchEduLLMDetect/main.py", line 70, in <module>
    run(args=args)
    │        └ Namespace(models=['detect-gpt', 'ghostbuster'], dataset='brat-project/dipper/llama-3.3-70b-instruct/131538', device='cuda:0',...
    └ <function run at 0x7a3c94e872e0>

  File "/homes/lgehring/projects/BenchEduLLMDetect/main.py", line 40, in run
    ghostbuster.run(data, args)
    │           │   │     └ Namespace(models=['detect-gpt', 'ghostbuster'], dataset='brat-project/dipper/llama-3.3-70b-instruct/131538', device='cuda:0',...
    │           │   └                                               question  ...                                                llm
    │           │     0    Some peop...
    │           └ <function run at 0x7a3b99e5aef0>
    └ <module 'detectors.ghostbuster.ghostbuster' from '/homes/lgehring/projects/BenchEduLLMDetect/detectors/ghostbuster/ghostbuste...

  File "/homes/lgehring/projects/BenchEduLLMDetect/detectors/ghostbuster/ghostbuster.py", line 99, in run
    enc = tiktoken.encoding_for_model("davinci-002")
          │        └ <function encoding_for_model at 0x7a3b9b19b400>
          └ <module 'tiktoken' from '/homes/lgehring/miniconda3/envs/BenchEduLLMDetect/lib/python3.10/site-packages/tiktoken/__init__.py'>

  File "/homes/lgehring/miniconda3/envs/BenchEduLLMDetect/lib/python3.10/site-packages/tiktoken/model.py", line 105, in encoding_for_model
    return get_encoding(encoding_name_for_model(model_name))
           │            │                       └ 'davinci-002'
           │            └ <function encoding_name_for_model at 0x7a3b9b19b010>
           └ <function get_encoding at 0x7a3b9b19b2e0>
  File "/homes/lgehring/miniconda3/envs/BenchEduLLMDetect/lib/python3.10/site-packages/tiktoken/registry.py", line 86, in get_encoding
    enc = Encoding(**constructor())
          │          └ <function cl100k_base at 0x7a3b99ebda20>
          └ <class 'tiktoken.core.Encoding'>
  File "/homes/lgehring/miniconda3/envs/BenchEduLLMDetect/lib/python3.10/site-packages/tiktoken_ext/openai_public.py", line 76, in cl100k_base
    mergeable_ranks = load_tiktoken_bpe(
                      └ <function load_tiktoken_bpe at 0x7a3b99ebd7e0>
  File "/homes/lgehring/miniconda3/envs/BenchEduLLMDetect/lib/python3.10/site-packages/tiktoken/load.py", line 144, in load_tiktoken_bpe
    contents = read_file_cached(tiktoken_bpe_file, expected_hash)
               │                │                  └ '223921b76ee99bde995b7ff738513eef100fb51d18c93597a113bcffe865b2a7'
               │                └ 'https://openaipublic.blob.core.windows.net/encodings/cl100k_base.tiktoken'
               └ <function read_file_cached at 0x7a3b99ebd630>
  File "/homes/lgehring/miniconda3/envs/BenchEduLLMDetect/lib/python3.10/site-packages/tiktoken/load.py", line 63, in read_file_cached
    contents = read_file(blobpath)
               │         └ 'https://openaipublic.blob.core.windows.net/encodings/cl100k_base.tiktoken'
               └ <function read_file at 0x7a3b99ebd480>
  File "/homes/lgehring/miniconda3/envs/BenchEduLLMDetect/lib/python3.10/site-packages/tiktoken/load.py", line 24, in read_file
    resp = requests.get(blobpath)
           │        │   └ 'https://openaipublic.blob.core.windows.net/encodings/cl100k_base.tiktoken'
           │        └ <function get at 0x7a3ba9f04e50>
           └ <module 'requests' from '/homes/lgehring/miniconda3/envs/BenchEduLLMDetect/lib/python3.10/site-packages/requests/__init__.py'>
  File "/homes/lgehring/miniconda3/envs/BenchEduLLMDetect/lib/python3.10/site-packages/requests/api.py", line 73, in get
    return request("get", url, params=params, **kwargs)
           │              │           │         └ {}
           │              │           └ None
           │              └ 'https://openaipublic.blob.core.windows.net/encodings/cl100k_base.tiktoken'
           └ <function request at 0x7a3ba9ed93f0>
  File "/homes/lgehring/miniconda3/envs/BenchEduLLMDetect/lib/python3.10/site-packages/requests/api.py", line 59, in request
    return session.request(method=method, url=url, **kwargs)
           │       │              │           │      └ {'params': None}
           │       │              │           └ 'https://openaipublic.blob.core.windows.net/encodings/cl100k_base.tiktoken'
           │       │              └ 'get'
           │       └ <function Session.request at 0x7a3ba9f045e0>
           └ <requests.sessions.Session object at 0x7a3b99e75570>
  File "/homes/lgehring/miniconda3/envs/BenchEduLLMDetect/lib/python3.10/site-packages/requests/sessions.py", line 589, in request
    resp = self.send(prep, **send_kwargs)
           │    │    │       └ {'timeout': None, 'allow_redirects': True, 'proxies': OrderedDict(), 'stream': False, 'verify': True, 'cert': None}
           │    │    └ <PreparedRequest [GET]>
           │    └ <function Session.send at 0x7a3ba9f04a60>
           └ <requests.sessions.Session object at 0x7a3b99e75570>
  File "/homes/lgehring/miniconda3/envs/BenchEduLLMDetect/lib/python3.10/site-packages/requests/sessions.py", line 703, in send
    r = adapter.send(request, **kwargs)
        │       │    │          └ {'timeout': None, 'proxies': OrderedDict(), 'stream': False, 'verify': True, 'cert': None}
        │       │    └ <PreparedRequest [GET]>
        │       └ <function HTTPAdapter.send at 0x7a3ba9f17eb0>
        └ <requests.adapters.HTTPAdapter object at 0x7a3b99e74af0>
  File "/homes/lgehring/miniconda3/envs/BenchEduLLMDetect/lib/python3.10/site-packages/requests/adapters.py", line 700, in send
    raise ConnectionError(e, request=request)
          │                          └ <PreparedRequest [GET]>
          └ <class 'requests.exceptions.ConnectionError'>

requests.exceptions.ConnectionError: HTTPSConnectionPool(host='openaipublic.blob.core.windows.net', port=443): Max retries exceeded with url: /encodings/cl100k_base.tiktoken (Caused by NameResolutionError("<urllib3.connection.HTTPSConnection object at 0x7a3b99e74f40>: Failed to resolve 'openaipublic.blob.core.windows.net' ([Errno -3] Temporary failure in name resolution)"))
